Workbook
Name UPDATE: 'Data Sheet'!$E$1

Sheet Dates Setting
C1: 43466 | D1: =C2+1 -> 43831 | E1: =D2+1 -> 44197 | F1: =E2+1 -> 44562 | G1: =F2+1 -> 44927 | H1: =G2+1 -> 45292 | I1: =H2+1 -> 45658 | J1: =I2+1 -> 46023 | K1: =J2+1 -> 46388 | ... O1: =N2+1 -> 47849
C2: =EOMONTH(C1,$B$7-1) -> 43830 | D2: =EOMONTH(D1,$B$7-1) -> 44196 | E2: =EOMONTH(E1,$B$7-1) -> 44561 | F2: =EOMONTH(F1,$B$7-1) -> 44926 | G2: =EOMONTH(G1,$B$7-1) -> 45291 | H2: =EOMONTH(H1,$B$7-1) -> 45657 | I2: =EOMONTH(I1,$B$7-1) -> 46022 | J2: =EOMONTH(J1,$B$7-1) -> 46387 | ... O2: =EOMONTH(O1,$B$7-1) -> 48213
A5: Current date | B5: 45853
A6: Model Period | B6: Y
A7: Months in Period | B7: =IF($B$6="Y",12,IF($B$6="Q",3,1)) -> 12
A9: Year | B9: =DATE(C9,1,1) -> 45658 | C9: =YEAR(B5) -> 2025
A10: Quarter
A11: Month

Sheet P&L Analysis
C2: ="Analysis sheet of" & " " &'Data Sheet'!B1 -> Analysis sheet of AVANTEL LTD
D3: 41729 | E3: 42094 | F3: 42460 | G3: 42825 | H3: 43190 | I3: 43555 | J3: 43921 | K3: 44286 | L3: 44651 | M3: 45016 | N3: 45382 | O3: 45747 | P3: 46112 | Q3: 46477 | R3: 46843 | S3: 47208 | T3: 47573
D4: Actual | E4: Actual | F4: Actual | G4: Actual | H4: Actual | I4: Actual | J4: Actual | K4: Actual | L4: Actual | M4: Actual | N4: Actual | O4: Actual | P4: Forecast | Q4: Forecast | R4: Forecast | S4: Forecast | T4: Forecast
B5: A. | C5: Income
C6: Sales | D6: =IFERROR(INDEX('Data Sheet'!$B$17:$O$31, MATCH($C6, 'Data Sheet'!$A$17:$A$31, 0), MATCH(D$3, 'Data Sheet'!$B$16:$O$16, 0)), 0) -> 0 | E6: =IFERROR(INDEX('Data Sheet'!$B$17:$O$31, MATCH($C6, 'Data Sheet'!$A$17:$A$31, 0), MATCH(E$3, 'Data Sheet'!$B$16:$O$16, 0)), 0) -> 0 | F6: =IFERROR(INDEX('Data Sheet'!$B$17:$O$31, MATCH($C6, 'Data Sheet'!$A$17:$A$31, 0), MATCH(F$3, 'Data Sheet'!$B$16:$O$16, 0)), 0) -> 24.63 | G6: =IFERROR(INDEX('Data Sheet'!$B$17:$O$31, MATCH($C6, 'Data Sheet'!$A$17:$A$31, 0), MATCH(G$3, 'Data Sheet'!$B$16:$O$16, 0)), 0) -> 33.58 | H6: =IFERROR(INDEX('Data Sheet'!$B$17:$O$31, MATCH($C6, 'Data Sheet'!$A$17:$A$31, 0), MATCH(H$3, 'Data Sheet'!$B$16:$O$16, 0)), 0) -> 51.7 | I6: =IFERROR(INDEX('Data Sheet'!$B$17:$O$31, MATCH($C6, 'Data Sheet'!$A$17:$A$31, 0), MATCH(I$3, 'Data Sheet'!$B$16:$O$16, 0)), 0) -> 50.51 | J6: =IFERROR(INDEX('Data Sheet'!$B$17:$O$31, MATCH($C6, 'Data Sheet'!$A$17:$A$31, 0), MATCH(J$3, 'Data Sheet'!$B$16:$O$16, 0)), 0) -> 51.92 | K6: =IFERROR(INDEX('Data Sheet'!$B$17:$O$31, MATCH($C6, 'Data Sheet'!$A$17:$A$31, 0), MATCH(K$3, 'Data Sheet'!$B$16:$O$16, 0)), 0) -> 77.69 | ... T6: =IFERROR(INDEX('Data Sheet'!$B$17:$O$31, MATCH($C6, 'Data Sheet'!$A$17:$A$31, 0), MATCH(T$3, 'Data Sheet'!$B$16:$O$16, 0)), 0) -> 0
C7: Other Income | D7: =IFERROR(INDEX('Data Sheet'!$B$17:$O$31, MATCH($C7, 'Data Sheet'!$A$17:$A$31, 0), MATCH(D$3, 'Data Sheet'!$B$16:$O$16, 0)), 0) -> 0 | E7: =IFERROR(INDEX('Data Sheet'!$B$17:$O$31, MATCH($C7, 'Data Sheet'!$A$17:$A$31, 0), MATCH(E$3, 'Data Sheet'!$B$16:$O$16, 0)), 0) -> 0 | F7: =IFERROR(INDEX('Data Sheet'!$B$17:$O$31, MATCH($C7, 'Data Sheet'!$A$17:$A$31, 0), MATCH(F$3, 'Data Sheet'!$B$16:$O$16, 0)), 0) -> 0.4 | G7: =IFERROR(INDEX('Data Sheet'!$B$17:$O$31, MATCH($C7, 'Data Sheet'!$A$17:$A$31, 0), MATCH(G$3, 'Data Sheet'!$B$16:$O$16, 0)), 0) -> 0.51 | H7: =IFERROR(INDEX('Data Sheet'!$B$17:$O$31, MATCH($C7, 'Data Sheet'!$A$17:$A$31, 0), MATCH(H$3, 'Data Sheet'!$B$16:$O$16, 0)), 0) -> 15.44 | I7: =IFERROR(INDEX('Data Sheet'!$B$17:$O$31, MATCH($C7, 'Data Sheet'!$A$17:$A$31, 0), MATCH(I$3, 'Data Sheet'!$B$16:$O$16, 0)), 0) -> 0.91 | J7: =IFERROR(INDEX('Data Sheet'!$B$17:$O$31, MATCH($C7, 'Data Sheet'!$A$17:$A$31, 0), MATCH(J$3, 'Data Sheet'!$B$16:$O$16, 0)), 0) -> 1.2 | K7: =IFERROR(INDEX('Data Sheet'!$B$17:$O$31, MATCH($C7, 'Data Sheet'!$A$17:$A$31, 0), MATCH(K$3, 'Data Sheet'!$B$16:$O$16, 0)), 0) -> 0.87 | ... T7: =IFERROR(INDEX('Data Sheet'!$B$17:$O$31, MATCH($C7, 'Data Sheet'!$A$17:$A$31, 0), MATCH(T$3, 'Data Sheet'!$B$16:$O$16, 0)), 0) -> 0
C9: Total Income | D9: =D6+D7 -> 0 | E9: =E6+E7 -> 0 | F9: =F6+F7 -> 25.03 | G9: =G6+G7 -> 34.09 | H9: =H6+H7 -> 67.14 | I9: =I6+I7 -> 51.42 | J9: =J6+J7 -> 53.12 | K9: =K6+K7 -> 78.56 | ... T9: =T6+T7 -> 0
C10: Other Income % of TI | D10: =IFERROR(D7/D9,0) -> 0 | E10: =IFERROR(E7/E9,0) -> 0 | F10: =IFERROR(F7/F9,0) -> 0.015980823 | G10: =IFERROR(G7/G9,0) -> 0.014960399 | H10: =IFERROR(H7/H9,0) -> 0.22996723 | I10: =IFERROR(I7/I9,0) -> 0.017697394 | J10: =IFERROR(J7/J9,0) -> 0.022590361 | K10: =IFERROR(K7/K9,0) -> 0.011074338 | ... T10: =IFERROR(T7/T9,0) -> 0
B12: B. | C12: Operating Expense
C14: Raw Material Cost | D14: =IFERROR(INDEX('Data Sheet'!$B$17:$O$31, MATCH($C14, 'Data Sheet'!$A$17:$A$31, 0), MATCH(D$3, 'Data Sheet'!$B$16:$O$16, 0)), 0) -> 0 | E14: =IFERROR(INDEX('Data Sheet'!$B$17:$O$31, MATCH($C14, 'Data Sheet'!$A$17:$A$31, 0), MATCH(E$3, 'Data Sheet'!$B$16:$O$16, 0)), 0) -> 0 | F14: =IFERROR(INDEX('Data Sheet'!$B$17:$O$31, MATCH($C14, 'Data Sheet'!$A$17:$A$31, 0), MATCH(F$3, 'Data Sheet'!$B$16:$O$16, 0)), 0) -> 9.69 | G14: =IFERROR(INDEX('Data Sheet'!$B$17:$O$31, MATCH($C14, 'Data Sheet'!$A$17:$A$31, 0), MATCH(G$3, 'Data Sheet'!$B$16:$O$16, 0)), 0) -> 10.02 | H14: =IFERROR(INDEX('Data Sheet'!$B$17:$O$31, MATCH($C14, 'Data Sheet'!$A$17:$A$31, 0), MATCH(H$3, 'Data Sheet'!$B$16:$O$16, 0)), 0) -> 17.5 | I14: =IFERROR(INDEX('Data Sheet'!$B$17:$O$31, MATCH($C14, 'Data Sheet'!$A$17:$A$31, 0), MATCH(I$3, 'Data Sheet'!$B$16:$O$16, 0)), 0) -> 11.3 | J14: =IFERROR(INDEX('Data Sheet'!$B$17:$O$31, MATCH($C14, 'Data Sheet'!$A$17:$A$31, 0), MATCH(J$3, 'Data Sheet'!$B$16:$O$16, 0)), 0) -> 13.95 | K14: =IFERROR(INDEX('Data Sheet'!$B$17:$O$31, MATCH($C14, 'Data Sheet'!$A$17:$A$31, 0), MATCH(K$3, 'Data Sheet'!$B$16:$O$16, 0)), 0) -> 26.57 | ... T14: =IFERROR(INDEX('Data Sheet'!$B$17:$O$31, MATCH($C14, 'Data Sheet'!$A$17:$A$31, 0), MATCH(T$3, 'Data Sheet'!$B$16:$O$16, 0)), 0) -> 0
C15: Change in Inventory | D15: =IFERROR(INDEX('Data Sheet'!$B$17:$O$31, MATCH($C15, 'Data Sheet'!$A$17:$A$31, 0), MATCH(D$3, 'Data Sheet'!$B$16:$O$16, 0)), 0) -> 0 | E15: =IFERROR(INDEX('Data Sheet'!$B$17:$O$31, MATCH($C15, 'Data Sheet'!$A$17:$A$31, 0), MATCH(E$3, 'Data Sheet'!$B$16:$O$16, 0)), 0) -> 0 | F15: =IFERROR(INDEX('Data Sheet'!$B$17:$O$31, MATCH($C15, 'Data Sheet'!$A$17:$A$31, 0), MATCH(F$3, 'Data Sheet'!$B$16:$O$16, 0)), 0) -> 1.45 | G15: =IFERROR(INDEX('Data Sheet'!$B$17:$O$31, MATCH($C15, 'Data Sheet'!$A$17:$A$31, 0), MATCH(G$3, 'Data Sheet'!$B$16:$O$16, 0)), 0) -> -4.77 | H15: =IFERROR(INDEX('Data Sheet'!$B$17:$O$31, MATCH($C15, 'Data Sheet'!$A$17:$A$31, 0), MATCH(H$3, 'Data Sheet'!$B$16:$O$16, 0)), 0) -> -2.42 | I15: =IFERROR(INDEX('Data Sheet'!$B$17:$O$31, MATCH($C15, 'Data Sheet'!$A$17:$A$31, 0), MATCH(I$3, 'Data Sheet'!$B$16:$O$16, 0)), 0) -> -2.99 | J15: =IFERROR(INDEX('Data Sheet'!$B$17:$O$31, MATCH($C15, 'Data Sheet'!$A$17:$A$31, 0), MATCH(J$3, 'Data Sheet'!$B$16:$O$16, 0)), 0) -> 0.59 | K15: =IFERROR(INDEX('Data Sheet'!$B$17:$O$31, MATCH($C15, 'Data Sheet'!$A$17:$A$31, 0), MATCH(K$3, 'Data Sheet'!$B$16:$O$16, 0)), 0) -> -0.42 | ... T15: =IFERROR(INDEX('Data Sheet'!$B$17:$O$31, MATCH($C15, 'Data Sheet'!$A$17:$A$31, 0), MATCH(T$3, 'Data Sheet'!$B$16:$O$16, 0)), 0) -> 0
C16: Power and Fuel | D16: =IFERROR(INDEX('Data Sheet'!$B$17:$O$31, MATCH($C16, 'Data Sheet'!$A$17:$A$31, 0), MATCH(D$3, 'Data Sheet'!$B$16:$O$16, 0)), 0) -> 0 | E16: =IFERROR(INDEX('Data Sheet'!$B$17:$O$31, MATCH($C16, 'Data Sheet'!$A$17:$A$31, 0), MATCH(E$3, 'Data Sheet'!$B$16:$O$16, 0)), 0) -> 0 | F16: =IFERROR(INDEX('Data Sheet'!$B$17:$O$31, MATCH($C16, 'Data Sheet'!$A$17:$A$31, 0), MATCH(F$3, 'Data Sheet'!$B$16:$O$16, 0)), 0) -> 0.32 | G16: =IFERROR(INDEX('Data Sheet'!$B$17:$O$31, MATCH($C16, 'Data Sheet'!$A$17:$A$31, 0), MATCH(G$3, 'Data Sheet'!$B$16:$O$16, 0)), 0) -> 0.31 | H16: =IFERROR(INDEX('Data Sheet'!$B$17:$O$31, MATCH($C16, 'Data Sheet'!$A$17:$A$31, 0), MATCH(H$3, 'Data Sheet'!$B$16:$O$16, 0)), 0) -> 0.43 | I16: =IFERROR(INDEX('Data Sheet'!$B$17:$O$31, MATCH($C16, 'Data Sheet'!$A$17:$A$31, 0), MATCH(I$3, 'Data Sheet'!$B$16:$O$16, 0)), 0) -> 0.47 | J16: =IFERROR(INDEX('Data Sheet'!$B$17:$O$31, MATCH($C16, 'Data Sheet'!$A$17:$A$31, 0), MATCH(J$3, 'Data Sheet'!$B$16:$O$16, 0)), 0) -> 0.43 | K16: =IFERROR(INDEX('Data Sheet'!$B$17:$O$31, MATCH($C16, 'Data Sheet'!$A$17:$A$31, 0), MATCH(K$3, 'Data Sheet'!$B$16:$O$16, 0)), 0) -> 0.52 | ... T16: =IFERROR(INDEX('Data Sheet'!$B$17:$O$31, MATCH($C16, 'Data Sheet'!$A$17:$A$31, 0), MATCH(T$3, 'Data Sheet'!$B$16:$O$16, 0)), 0) -> 0
C17: Other Mfr. Exp | D17: =IFERROR(INDEX('Data Sheet'!$B$17:$O$31, MATCH($C17, 'Data Sheet'!$A$17:$A$31, 0), MATCH(D$3, 'Data Sheet'!$B$16:$O$16, 0)), 0) -> 0 | E17: =IFERROR(INDEX('Data Sheet'!$B$17:$O$31, MATCH($C17, 'Data Sheet'!$A$17:$A$31, 0), MATCH(E$3, 'Data Sheet'!$B$16:$O$16, 0)), 0) -> 0 | F17: =IFERROR(INDEX('Data Sheet'!$B$17:$O$31, MATCH($C17, 'Data Sheet'!$A$17:$A$31, 0), MATCH(F$3, 'Data Sheet'!$B$16:$O$16, 0)), 0) -> 2.04 | G17: =IFERROR(INDEX('Data Sheet'!$B$17:$O$31, MATCH($C17, 'Data Sheet'!$A$17:$A$31, 0), MATCH(G$3, 'Data Sheet'!$B$16:$O$16, 0)), 0) -> 2.06 | H17: =IFERROR(INDEX('Data Sheet'!$B$17:$O$31, MATCH($C17, 'Data Sheet'!$A$17:$A$31, 0), MATCH(H$3, 'Data Sheet'!$B$16:$O$16, 0)), 0) -> 3.09 | I17: =IFERROR(INDEX('Data Sheet'!$B$17:$O$31, MATCH($C17, 'Data Sheet'!$A$17:$A$31, 0), MATCH(I$3, 'Data Sheet'!$B$16:$O$16, 0)), 0) -> 4.9 | J17: =IFERROR(INDEX('Data Sheet'!$B$17:$O$31, MATCH($C17, 'Data Sheet'!$A$17:$A$31, 0), MATCH(J$3, 'Data Sheet'!$B$16:$O$16, 0)), 0) -> 5.14 | K17: =IFERROR(INDEX('Data Sheet'!$B$17:$O$31, MATCH($C17, 'Data Sheet'!$A$17:$A$31, 0), MATCH(K$3, 'Data Sheet'!$B$16:$O$16, 0)), 0) -> 8.88 | ... T17: =IFERROR(INDEX('Data Sheet'!$B$17:$O$31, MATCH($C17, 'Data Sheet'!$A$17:$A$31, 0), MATCH(T$3, 'Data Sheet'!$B$16:$O$16, 0)), 0) -> 0
C18: Employee Cost | D18: =IFERROR(INDEX('Data Sheet'!$B$17:$O$31, MATCH($C18, 'Data Sheet'!$A$17:$A$31, 0), MATCH(D$3, 'Data Sheet'!$B$16:$O$16, 0)), 0) -> 0 | E18: =IFERROR(INDEX('Data Sheet'!$B$17:$O$31, MATCH($C18, 'Data Sheet'!$A$17:$A$31, 0), MATCH(E$3, 'Data Sheet'!$B$16:$O$16, 0)), 0) -> 0 | F18: =IFERROR(INDEX('Data Sheet'!$B$17:$O$31, MATCH($C18, 'Data Sheet'!$A$17:$A$31, 0), MATCH(F$3, 'Data Sheet'!$B$16:$O$16, 0)), 0) -> 4.15 | G18: =IFERROR(INDEX('Data Sheet'!$B$17:$O$31, MATCH($C18, 'Data Sheet'!$A$17:$A$31, 0), MATCH(G$3, 'Data Sheet'!$B$16:$O$16, 0)), 0) -> 4.85 | H18: =IFERROR(INDEX('Data Sheet'!$B$17:$O$31, MATCH($C18, 'Data Sheet'!$A$17:$A$31, 0), MATCH(H$3, 'Data Sheet'!$B$16:$O$16, 0)), 0) -> 7.83 | I18: =IFERROR(INDEX('Data Sheet'!$B$17:$O$31, MATCH($C18, 'Data Sheet'!$A$17:$A$31, 0), MATCH(I$3, 'Data Sheet'!$B$16:$O$16, 0)), 0) -> 8.49 | J18: =IFERROR(INDEX('Data Sheet'!$B$17:$O$31, MATCH($C18, 'Data Sheet'!$A$17:$A$31, 0), MATCH(J$3, 'Data Sheet'!$B$16:$O$16, 0)), 0) -> 10.1 | K18: =IFERROR(INDEX('Data Sheet'!$B$17:$O$31, MATCH($C18, 'Data Sheet'!$A$17:$A$31, 0), MATCH(K$3, 'Data Sheet'!$B$16:$O$16, 0)), 0) -> 10.43 | ... T18: =IFERROR(INDEX('Data Sheet'!$B$17:$O$31, MATCH($C18, 'Data Sheet'!$A$17:$A$31, 0), MATCH(T$3, 'Data Sheet'!$B$16:$O$16, 0)), 0) -> 0
C19: Selling and admin | D19: =IFERROR(INDEX('Data Sheet'!$B$17:$O$31, MATCH($C19, 'Data Sheet'!$A$17:$A$31, 0), MATCH(D$3, 'Data Sheet'!$B$16:$O$16, 0)), 0) -> 0 | E19: =IFERROR(INDEX('Data Sheet'!$B$17:$O$31, MATCH($C19, 'Data Sheet'!$A$17:$A$31, 0), MATCH(E$3, 'Data Sheet'!$B$16:$O$16, 0)), 0) -> 0 | F19: =IFERROR(INDEX('Data Sheet'!$B$17:$O$31, MATCH($C19, 'Data Sheet'!$A$17:$A$31, 0), MATCH(F$3, 'Data Sheet'!$B$16:$O$16, 0)), 0) -> 5.73 | G19: =IFERROR(INDEX('Data Sheet'!$B$17:$O$31, MATCH($C19, 'Data Sheet'!$A$17:$A$31, 0), MATCH(G$3, 'Data Sheet'!$B$16:$O$16, 0)), 0) -> 7.36 | H19: =IFERROR(INDEX('Data Sheet'!$B$17:$O$31, MATCH($C19, 'Data Sheet'!$A$17:$A$31, 0), MATCH(H$3, 'Data Sheet'!$B$16:$O$16, 0)), 0) -> 8.28 | I19: =IFERROR(INDEX('Data Sheet'!$B$17:$O$31, MATCH($C19, 'Data Sheet'!$A$17:$A$31, 0), MATCH(I$3, 'Data Sheet'!$B$16:$O$16, 0)), 0) -> 7.95 | J19: =IFERROR(INDEX('Data Sheet'!$B$17:$O$31, MATCH($C19, 'Data Sheet'!$A$17:$A$31, 0), MATCH(J$3, 'Data Sheet'!$B$16:$O$16, 0)), 0) -> 7.09 | K19: =IFERROR(INDEX('Data Sheet'!$B$17:$O$31, MATCH($C19, 'Data Sheet'!$A$17:$A$31, 0), MATCH(K$3, 'Data Sheet'!$B$16:$O$16, 0)), 0) -> 8.32 | ... T19: =IFERROR(INDEX('Data Sheet'!$B$17:$O$31, MATCH($C19, 'Data Sheet'!$A$17:$A$31, 0), MATCH(T$3, 'Data Sheet'!$B$16:$O$16, 0)), 0) -> 0
C20: Other Expenses | D20: =IFERROR(INDEX('Data Sheet'!$B$17:$O$31, MATCH($C20, 'Data Sheet'!$A$17:$A$31, 0), MATCH(D$3, 'Data Sheet'!$B$16:$O$16, 0)), 0) -> 0 | E20: =IFERROR(INDEX('Data Sheet'!$B$17:$O$31, MATCH($C20, 'Data Sheet'!$A$17:$A$31, 0), MATCH(E$3, 'Data Sheet'!$B$16:$O$16, 0)), 0) -> 0 | F20: =IFERROR(INDEX('Data Sheet'!$B$17:$O$31, MATCH($C20, 'Data Sheet'!$A$17:$A$31, 0), MATCH(F$3, 'Data Sheet'!$B$16:$O$16, 0)), 0) -> 0.22 | G20: =IFERROR(INDEX('Data Sheet'!$B$17:$O$31, MATCH($C20, 'Data Sheet'!$A$17:$A$31, 0), MATCH(G$3, 'Data Sheet'!$B$16:$O$16, 0)), 0) -> 0.35 | H20: =IFERROR(INDEX('Data Sheet'!$B$17:$O$31, MATCH($C20, 'Data Sheet'!$A$17:$A$31, 0), MATCH(H$3, 'Data Sheet'!$B$16:$O$16, 0)), 0) -> 0.89 | I20: =IFERROR(INDEX('Data Sheet'!$B$17:$O$31, MATCH($C20, 'Data Sheet'!$A$17:$A$31, 0), MATCH(I$3, 'Data Sheet'!$B$16:$O$16, 0)), 0) -> 0.19 | J20: =IFERROR(INDEX('Data Sheet'!$B$17:$O$31, MATCH($C20, 'Data Sheet'!$A$17:$A$31, 0), MATCH(J$3, 'Data Sheet'!$B$16:$O$16, 0)), 0) -> 0.43 | K20: =IFERROR(INDEX('Data Sheet'!$B$17:$O$31, MATCH($C20, 'Data Sheet'!$A$17:$A$31, 0), MATCH(K$3, 'Data Sheet'!$B$16:$O$16, 0)), 0) -> 0.38 | ... T20: =IFERROR(INDEX('Data Sheet'!$B$17:$O$31, MATCH($C20, 'Data Sheet'!$A$17:$A$31, 0), MATCH(T$3, 'Data Sheet'!$B$16:$O$16, 0)), 0) -> 0
C22: Total OE | D22: =D14-D15+SUM(D16:D20) -> 0 | E22: =E14-E15+SUM(E16:E20) -> 0 | F22: =F14-F15+SUM(F16:F20) -> 20.7 | G22: =G14-G15+SUM(G16:G20) -> 29.72 | H22: =H14-H15+SUM(H16:H20) -> 40.44 | I22: =I14-I15+SUM(I16:I20) -> 36.29 | J22: =J14-J15+SUM(J16:J20) -> 36.55 | K22: =K14-K15+SUM(K16:K20) -> 55.52 | ... T22: =T14-T15+SUM(T16:T20) -> 0
B24: C. | C24: EBIDTA | D24: =D6-D22 -> 0 | E24: =E6-E22 -> 0 | F24: =F6-F22 -> 3.93 | G24: =G6-G22 -> 3.86 | H24: =H6-H22 -> 11.26 | I24: =I6-I22 -> 14.22 | J24: =J6-J22 -> 15.37 | K24: =K6-K22 -> 22.17 | ... O24: =O6-O22 -> 95.39 | P24: =P9-P22 -> 0 | Q24: =Q9-Q22 -> 0 | R24: =R9-R22 -> 0 | S24: =S9-S22 -> 0 | T24: =T9-T22 -> 0
C25: EBIDTA (%) | D25: =IFERROR(D$24/D$6,0) -> 0 | E25: =IFERROR(E$24/E$6,0) -> 0 | F25: =IFERROR(F$24/F$6,0) -> 0.15956151 | G25: =IFERROR(G$24/G$6,0) -> 0.11494937 | H25: =IFERROR(H$24/H$6,0) -> 0.21779497 | I25: =IFERROR(I$24/I$6,0) -> 0.28152841 | J25: =IFERROR(J$24/J$6,0) -> 0.29603236 | K25: =IFERROR(K$24/K$6,0) -> 0.28536491 | ... T25: =IFERROR(T$24/T$6,0) -> 0
B27: D. | C27: Other Expense
C28: Depreciation | D28: =IFERROR(INDEX('Data Sheet'!$B$17:$O$31, MATCH($C28, 'Data Sheet'!$A$17:$A$31, 0), MATCH(D$3, 'Data Sheet'!$B$16:$O$16, 0)), 0) -> 0 | E28: =IFERROR(INDEX('Data Sheet'!$B$17:$O$31, MATCH($C28, 'Data Sheet'!$A$17:$A$31, 0), MATCH(E$3, 'Data Sheet'!$B$16:$O$16, 0)), 0) -> 0 | F28: =IFERROR(INDEX('Data Sheet'!$B$17:$O$31, MATCH($C28, 'Data Sheet'!$A$17:$A$31, 0), MATCH(F$3, 'Data Sheet'!$B$16:$O$16, 0)), 0) -> 1.74 | G28: =IFERROR(INDEX('Data Sheet'!$B$17:$O$31, MATCH($C28, 'Data Sheet'!$A$17:$A$31, 0), MATCH(G$3, 'Data Sheet'!$B$16:$O$16, 0)), 0) -> 1.79 | H28: =IFERROR(INDEX('Data Sheet'!$B$17:$O$31, MATCH($C28, 'Data Sheet'!$A$17:$A$31, 0), MATCH(H$3, 'Data Sheet'!$B$16:$O$16, 0)), 0) -> 1.64 | I28: =IFERROR(INDEX('Data Sheet'!$B$17:$O$31, MATCH($C28, 'Data Sheet'!$A$17:$A$31, 0), MATCH(I$3, 'Data Sheet'!$B$16:$O$16, 0)), 0) -> 2.05 | J28: =IFERROR(INDEX('Data Sheet'!$B$17:$O$31, MATCH($C28, 'Data Sheet'!$A$17:$A$31, 0), MATCH(J$3, 'Data Sheet'!$B$16:$O$16, 0)), 0) -> 2.71 | K28: =IFERROR(INDEX('Data Sheet'!$B$17:$O$31, MATCH($C28, 'Data Sheet'!$A$17:$A$31, 0), MATCH(K$3, 'Data Sheet'!$B$16:$O$16, 0)), 0) -> 3.03 | ... T28: =IFERROR(INDEX('Data Sheet'!$B$17:$O$31, MATCH($C28, 'Data Sheet'!$A$17:$A$31, 0), MATCH(T$3, 'Data Sheet'!$B$16:$O$16, 0)), 0) -> 0
C29: Interest | D29: =IFERROR(INDEX('Data Sheet'!$B$17:$O$31, MATCH($C29, 'Data Sheet'!$A$17:$A$31, 0), MATCH(D$3, 'Data Sheet'!$B$16:$O$16, 0)), 0) -> 0 | E29: =IFERROR(INDEX('Data Sheet'!$B$17:$O$31, MATCH($C29, 'Data Sheet'!$A$17:$A$31, 0), MATCH(E$3, 'Data Sheet'!$B$16:$O$16, 0)), 0) -> 0 | F29: =IFERROR(INDEX('Data Sheet'!$B$17:$O$31, MATCH($C29, 'Data Sheet'!$A$17:$A$31, 0), MATCH(F$3, 'Data Sheet'!$B$16:$O$16, 0)), 0) -> 1.94 | G29: =IFERROR(INDEX('Data Sheet'!$B$17:$O$31, MATCH($C29, 'Data Sheet'!$A$17:$A$31, 0), MATCH(G$3, 'Data Sheet'!$B$16:$O$16, 0)), 0) -> 1.52 | H29: =IFERROR(INDEX('Data Sheet'!$B$17:$O$31, MATCH($C29, 'Data Sheet'!$A$17:$A$31, 0), MATCH(H$3, 'Data Sheet'!$B$16:$O$16, 0)), 0) -> 0.87 | I29: =IFERROR(INDEX('Data Sheet'!$B$17:$O$31, MATCH($C29, 'Data Sheet'!$A$17:$A$31, 0), MATCH(I$3, 'Data Sheet'!$B$16:$O$16, 0)), 0) -> 0.58 | J29: =IFERROR(INDEX('Data Sheet'!$B$17:$O$31, MATCH($C29, 'Data Sheet'!$A$17:$A$31, 0), MATCH(J$3, 'Data Sheet'!$B$16:$O$16, 0)), 0) -> 0.85 | K29: =IFERROR(INDEX('Data Sheet'!$B$17:$O$31, MATCH($C29, 'Data Sheet'!$A$17:$A$31, 0), MATCH(K$3, 'Data Sheet'!$B$16:$O$16, 0)), 0) -> 1.51 | ... T29: =IFERROR(INDEX('Data Sheet'!$B$17:$O$31, MATCH($C29, 'Data Sheet'!$A$17:$A$31, 0), MATCH(T$3, 'Data Sheet'!$B$16:$O$16, 0)), 0) -> 0
C31: Total Other Exp | D31: =D28+D29 -> 0 | E31: =E28+E29 -> 0 | F31: =F28+F29 -> 3.68 | G31: =G28+G29 -> 3.31 | H31: =H28+H29 -> 2.51 | I31: =I28+I29 -> 2.63 | J31: =J28+J29 -> 3.56 | K31: =K28+K29 -> 4.54 | ... T31: =T28+T29 -> 0
B33: E. | C33: PBT | D33: =D9-D22-D31 -> 0 | E33: =E9-E22-E31 -> 0 | F33: =F9-F22-F31 -> 0.65 | G33: =G9-G22-G31 -> 1.06 | H33: =H9-H22-H31 -> 24.19 | I33: =I9-I22-I31 -> 12.5 | J33: =J9-J22-J31 -> 13.01 | K33: =K9-K22-K31 -> 18.5 | ... T33: =T9-T22-T31 -> 0
B35: F. | C35: Tax | D35: =IFERROR(INDEX('Data Sheet'!$B$17:$O$31, MATCH($C35, 'Data Sheet'!$A$17:$A$31, 0), MATCH(D$3, 'Data Sheet'!$B$16:$O$16, 0)), 0) -> 0 | E35: =IFERROR(INDEX('Data Sheet'!$B$17:$O$31, MATCH($C35, 'Data Sheet'!$A$17:$A$31, 0), MATCH(E$3, 'Data Sheet'!$B$16:$O$16, 0)), 0) -> 0 | F35: =IFERROR(INDEX('Data Sheet'!$B$17:$O$31, MATCH($C35, 'Data Sheet'!$A$17:$A$31, 0), MATCH(F$3, 'Data Sheet'!$B$16:$O$16, 0)), 0) -> 0.06 | G35: =IFERROR(INDEX('Data Sheet'!$B$17:$O$31, MATCH($C35, 'Data Sheet'!$A$17:$A$31, 0), MATCH(G$3, 'Data Sheet'!$B$16:$O$16, 0)), 0) -> 0.17 | H35: =IFERROR(INDEX('Data Sheet'!$B$17:$O$31, MATCH($C35, 'Data Sheet'!$A$17:$A$31, 0), MATCH(H$3, 'Data Sheet'!$B$16:$O$16, 0)), 0) -> 6.88 | I35: =IFERROR(INDEX('Data Sheet'!$B$17:$O$31, MATCH($C35, 'Data Sheet'!$A$17:$A$31, 0), MATCH(I$3, 'Data Sheet'!$B$16:$O$16, 0)), 0) -> 2.91 | J35: =IFERROR(INDEX('Data Sheet'!$B$17:$O$31, MATCH($C35, 'Data Sheet'!$A$17:$A$31, 0), MATCH(J$3, 'Data Sheet'!$B$16:$O$16, 0)), 0) -> 2.26 | K35: =IFERROR(INDEX('Data Sheet'!$B$17:$O$31, MATCH($C35, 'Data Sheet'!$A$17:$A$31, 0), MATCH(K$3, 'Data Sheet'!$B$16:$O$16, 0)), 0) -> 3.17 | ... T35: =IFERROR(INDEX('Data Sheet'!$B$17:$O$31, MATCH($C35, 'Data Sheet'!$A$17:$A$31, 0), MATCH(T$3, 'Data Sheet'!$B$16:$O$16, 0)), 0) -> 0
B37: G. | C37: Net Profit | D37: =D33-D35 -> 0 | E37: =E33-E35 -> 0 | F37: =F33-F35 -> 0.59 | G37: =G33-G35 -> 0.89 | H37: =H33-H35 -> 17.31 | I37: =I33-I35 -> 9.59 | J37: =J33-J35 -> 10.75 | K37: =K33-K35 -> 15.33 | ... T37: =T33-T35 -> 0
C38: Net Profit Margin(%) | D38: =IFERROR((D$37/D$6),0) -> 0 | E38: =IFERROR((E$37/E$6),0) -> 0 | F38: =IFERROR((F$37/F$6),0) -> 0.023954527 | G38: =IFERROR((G$37/G$6),0) -> 0.026503871 | H38: =IFERROR((H$37/H$6),0) -> 0.33481625 | I38: =IFERROR((I$37/I$6),0) -> 0.18986339 | J38: =IFERROR((J$37/J$6),0) -> 0.20704931 | K38: =IFERROR((K$37/K$6),0) -> 0.19732269 | ... T38: =IFERROR((T$37/T$6),0) -> 0
C40: Growth Rates & Margin
C42: Sales Growth | E42: =IFERROR((E$6-D$6)/E$6,0) -> 0 | F42: =IFERROR((F$6-E$6)/F$6,0) -> 1 | G42: =IFERROR((G$6-F$6)/G$6,0) -> 0.2665277 | H42: =IFERROR((H$6-G$6)/H$6,0) -> 0.35048356 | I42: =IFERROR((I$6-H$6)/I$6,0) -> -0.023559691 | J42: =IFERROR((J$6-I$6)/J$6,0) -> 0.027157165 | K42: =IFERROR((K$6-J$6)/K$6,0) -> 0.33170292 | L42: =IFERROR((L$6-K$6)/L$6,0) -> 0.25967219 | ... R42: =IFERROR((R$6-Q$6)/R$6,0) -> 0
C43: EBIDTA Growth | E43: =IFERROR((E$24-D$24)/E$24,0) -> 0 | F43: =IFERROR((F$24-E$24)/F$24,0) -> 1 | G43: =IFERROR((G$24-F$24)/G$24,0) -> -0.018134715 | H43: =IFERROR((H$24-G$24)/H$24,0) -> 0.65719361 | I43: =IFERROR((I$24-H$24)/I$24,0) -> 0.20815752 | J43: =IFERROR((J$24-I$24)/J$24,0) -> 0.07482108 | K43: =IFERROR((K$24-J$24)/K$24,0) -> 0.30672079 | L43: =IFERROR((L$24-K$24)/L$24,0) -> 0.20108108 | ... R43: =IFERROR((R$24-Q$24)/R$24,0) -> 0
C44: Profitability Growth | E44: =IFERROR((E$37-D$37)/E$37,0) -> 0 | F44: =IFERROR((F$37-E$37)/F$37,0) -> 1 | G44: =IFERROR((G$37-F$37)/G$37,0) -> 0.33707865 | H44: =IFERROR((H$37-G$37)/H$37,0) -> 0.94858463 | I44: =IFERROR((I$37-H$37)/I$37,0) -> -0.80500521 | J44: =IFERROR((J$37-I$37)/J$37,0) -> 0.10790698 | K44: =IFERROR((K$37-J$37)/K$37,0) -> 0.2987606 | L44: =IFERROR((L$37-K$37)/L$37,0) -> 0.20072993 | ... R44: =IFERROR((R$37-Q$37)/R$37,0) -> 0
C47: Capex & Cash Flow
C49: Cash from Operating Activity | D49: =IFERROR(INDEX('Data Sheet'!$B$82:$O$85, MATCH($C49, 'Data Sheet'!$A$82:$A$85, 0), MATCH(D$3, 'Data Sheet'!$B$81:$O$81, 0)), 0) -> 0 | E49: =IFERROR(INDEX('Data Sheet'!$B$82:$O$85, MATCH($C49, 'Data Sheet'!$A$82:$A$85, 0), MATCH(E$3, 'Data Sheet'!$B$81:$O$81, 0)), 0) -> 0 | F49: =IFERROR(INDEX('Data Sheet'!$B$82:$O$85, MATCH($C49, 'Data Sheet'!$A$82:$A$85, 0), MATCH(F$3, 'Data Sheet'!$B$81:$O$81, 0)), 0) -> 3.58 | G49: =IFERROR(INDEX('Data Sheet'!$B$82:$O$85, MATCH($C49, 'Data Sheet'!$A$82:$A$85, 0), MATCH(G$3, 'Data Sheet'!$B$81:$O$81, 0)), 0) -> 1.78 | H49: =IFERROR(INDEX('Data Sheet'!$B$82:$O$85, MATCH($C49, 'Data Sheet'!$A$82:$A$85, 0), MATCH(H$3, 'Data Sheet'!$B$81:$O$81, 0)), 0) -> 9.12 | I49: =IFERROR(INDEX('Data Sheet'!$B$82:$O$85, MATCH($C49, 'Data Sheet'!$A$82:$A$85, 0), MATCH(I$3, 'Data Sheet'!$B$81:$O$81, 0)), 0) -> 4.21 | J49: =IFERROR(INDEX('Data Sheet'!$B$82:$O$85, MATCH($C49, 'Data Sheet'!$A$82:$A$85, 0), MATCH(J$3, 'Data Sheet'!$B$81:$O$81, 0)), 0) -> 3.04 | K49: =IFERROR(INDEX('Data Sheet'!$B$82:$O$85, MATCH($C49, 'Data Sheet'!$A$82:$A$85, 0), MATCH(K$3, 'Data Sheet'!$B$81:$O$81, 0)), 0) -> 44.65 | ... T49: =IFERROR(INDEX('Data Sheet'!$B$82:$O$85, MATCH($C49, 'Data Sheet'!$A$82:$A$85, 0), MATCH(T$3, 'Data Sheet'!$B$81:$O$81, 0)), 0) -> 0
C50: Depreciation | D50: =IFERROR(INDEX('Data Sheet'!$B$17:$O$31, MATCH($C50, 'Data Sheet'!$A$17:$A$31, 0), MATCH(D$3, 'Data Sheet'!$B$16:$O$16, 0)), 0) -> 0 | E50: =IFERROR(INDEX('Data Sheet'!$B$17:$O$31, MATCH($C50, 'Data Sheet'!$A$17:$A$31, 0), MATCH(E$3, 'Data Sheet'!$B$16:$O$16, 0)), 0) -> 0 | F50: =IFERROR(INDEX('Data Sheet'!$B$17:$O$31, MATCH($C50, 'Data Sheet'!$A$17:$A$31, 0), MATCH(F$3, 'Data Sheet'!$B$16:$O$16, 0)), 0) -> 1.74 | G50: =IFERROR(INDEX('Data Sheet'!$B$17:$O$31, MATCH($C50, 'Data Sheet'!$A$17:$A$31, 0), MATCH(G$3, 'Data Sheet'!$B$16:$O$16, 0)), 0) -> 1.79 | H50: =IFERROR(INDEX('Data Sheet'!$B$17:$O$31, MATCH($C50, 'Data Sheet'!$A$17:$A$31, 0), MATCH(H$3, 'Data Sheet'!$B$16:$O$16, 0)), 0) -> 1.64 | I50: =IFERROR(INDEX('Data Sheet'!$B$17:$O$31, MATCH($C50, 'Data Sheet'!$A$17:$A$31, 0), MATCH(I$3, 'Data Sheet'!$B$16:$O$16, 0)), 0) -> 2.05 | J50: =IFERROR(INDEX('Data Sheet'!$B$17:$O$31, MATCH($C50, 'Data Sheet'!$A$17:$A$31, 0), MATCH(J$3, 'Data Sheet'!$B$16:$O$16, 0)), 0) -> 2.71 | K50: =IFERROR(INDEX('Data Sheet'!$B$17:$O$31, MATCH($C50, 'Data Sheet'!$A$17:$A$31, 0), MATCH(K$3, 'Data Sheet'!$B$16:$O$16, 0)), 0) -> 3.03 | ... T50: =IFERROR(INDEX('Data Sheet'!$B$17:$O$31, MATCH($C50, 'Data Sheet'!$A$17:$A$31, 0), MATCH(T$3, 'Data Sheet'!$B$16:$O$16, 0)), 0) -> 0
C51: Capex Addition in the year (Change in (NFA+WIP)+Acc Depreciation) | D51: =BS!D30+'P&L Analysis'!D50 -> 0 | E51: =BS!E30+'P&L Analysis'!E50 -> 0 | F51: 0 | G51: =BS!G30+'P&L Analysis'!G50 -> 1.7 | H51: =BS!H30+'P&L Analysis'!H50 -> 0.44 | I51: =BS!I30+'P&L Analysis'!I50 -> 1.69 | J51: =BS!J30+'P&L Analysis'!J50 -> 5.19 | K51: =BS!K30+'P&L Analysis'!K50 -> 5.58 | L51: =BS!L30+'P&L Analysis'!L50 -> 18.91 | M51: =BS!M30+'P&L Analysis'!M50 -> 7.65 | N51: =BS!N30+'P&L Analysis'!N50 -> 32.95 | ... T51: =BS!T30+'P&L Analysis'!T50 -> 0
C53: Free Cash Flow (FCF= CF-Capex) | D53: =D49-D51 -> 0 | E53: =E49-E51 -> 0 | F53: 0 | G53: =G49-G51 -> 0.08 | H53: =H49-H51 -> 8.68 | I53: =I49-I51 -> 2.52 | J53: =J49-J51 -> -2.15 | K53: =K49-K51 -> 39.07 | L53: =L49-L51 -> -48.81 | M53: =M49-M51 -> -3.2 | N53: =N49-N51 -> 35.35 | ... T53: =T49-T51 -> 0
C55: Capital
C57: Total Debt
C58: Share Capital
C59: Dividend Paid
...

Sheet BS
D2: 41729 | E2: 42094 | F2: 42460 | G2: 42825 | H2: 43190 | I2: 43555 | J2: 43921 | K2: 44286 | L2: 44651 | M2: 45016 | N2: 45382 | O2: 45747 | P2: 46112 | Q2: 46477 | R2: 46843 | S2: 47208 | T2: 47573
D3: Actual | E3: Actual | F3: Actual | G3: Actual | H3: Actual | I3: Actual | J3: Actual | K3: Actual | L3: Actual | M3: Actual | N3: Actual | O3: Actual | P3: Forecast | Q3: Forecast | R3: Forecast | S3: Forecast | T3: Forecast
B4: A. | C4: Owners Fund
C5: Equity Share Capital | D5: =IFERROR(INDEX('Data Sheet'!$B$57:$O$72, MATCH($C5, 'Data Sheet'!$A$57:$A$72, 0), MATCH(D$2, 'Data Sheet'!$B$56:$O$56, 0)), 0) -> 0 | E5: =IFERROR(INDEX('Data Sheet'!$B$57:$O$72, MATCH($C5, 'Data Sheet'!$A$57:$A$72, 0), MATCH(E$2, 'Data Sheet'!$B$56:$O$56, 0)), 0) -> 0 | F5: =IFERROR(INDEX('Data Sheet'!$B$57:$O$72, MATCH($C5, 'Data Sheet'!$A$57:$A$72, 0), MATCH(F$2, 'Data Sheet'!$B$56:$O$56, 0)), 0) -> 4.06 | G5: =IFERROR(INDEX('Data Sheet'!$B$57:$O$72, MATCH($C5, 'Data Sheet'!$A$57:$A$72, 0), MATCH(G$2, 'Data Sheet'!$B$56:$O$56, 0)), 0) -> 4.06 | H5: =IFERROR(INDEX('Data Sheet'!$B$57:$O$72, MATCH($C5, 'Data Sheet'!$A$57:$A$72, 0), MATCH(H$2, 'Data Sheet'!$B$56:$O$56, 0)), 0) -> 4.06 | I5: =IFERROR(INDEX('Data Sheet'!$B$57:$O$72, MATCH($C5, 'Data Sheet'!$A$57:$A$72, 0), MATCH(I$2, 'Data Sheet'!$B$56:$O$56, 0)), 0) -> 4.06 | J5: =IFERROR(INDEX('Data Sheet'!$B$57:$O$72, MATCH($C5, 'Data Sheet'!$A$57:$A$72, 0), MATCH(J$2, 'Data Sheet'!$B$56:$O$56, 0)), 0) -> 4.06 | K5: =IFERROR(INDEX('Data Sheet'!$B$57:$O$72, MATCH($C5, 'Data Sheet'!$A$57:$A$72, 0), MATCH(K$2, 'Data Sheet'!$B$56:$O$56, 0)), 0) -> 4.06 | ... T5: =IFERROR(INDEX('Data Sheet'!$B$57:$O$72, MATCH($C5, 'Data Sheet'!$A$57:$A$72, 0), MATCH(T$2, 'Data Sheet'!$B$56:$O$56, 0)), 0) -> 0
C6: Reserves | D6: =IFERROR(INDEX('Data Sheet'!$B$57:$O$72, MATCH($C6, 'Data Sheet'!$A$57:$A$72, 0), MATCH(D$2, 'Data Sheet'!$B$56:$O$56, 0)), 0) -> 0 | E6: =IFERROR(INDEX('Data Sheet'!$B$57:$O$72, MATCH($C6, 'Data Sheet'!$A$57:$A$72, 0), MATCH(E$2, 'Data Sheet'!$B$56:$O$56, 0)), 0) -> 0 | F6: =IFERROR(INDEX('Data Sheet'!$B$57:$O$72, MATCH($C6, 'Data Sheet'!$A$57:$A$72, 0), MATCH(F$2, 'Data Sheet'!$B$56:$O$56, 0)), 0) -> 15.69 | G6: =IFERROR(INDEX('Data Sheet'!$B$57:$O$72, MATCH($C6, 'Data Sheet'!$A$57:$A$72, 0), MATCH(G$2, 'Data Sheet'!$B$56:$O$56, 0)), 0) -> 16.57 | H6: =IFERROR(INDEX('Data Sheet'!$B$57:$O$72, MATCH($C6, 'Data Sheet'!$A$57:$A$72, 0), MATCH(H$2, 'Data Sheet'!$B$56:$O$56, 0)), 0) -> 32.9 | I6: =IFERROR(INDEX('Data Sheet'!$B$57:$O$72, MATCH($C6, 'Data Sheet'!$A$57:$A$72, 0), MATCH(I$2, 'Data Sheet'!$B$56:$O$56, 0)), 0) -> 38.99 | J6: =IFERROR(INDEX('Data Sheet'!$B$57:$O$72, MATCH($C6, 'Data Sheet'!$A$57:$A$72, 0), MATCH(J$2, 'Data Sheet'!$B$56:$O$56, 0)), 0) -> 47.62 | K6: =IFERROR(INDEX('Data Sheet'!$B$57:$O$72, MATCH($C6, 'Data Sheet'!$A$57:$A$72, 0), MATCH(K$2, 'Data Sheet'!$B$56:$O$56, 0)), 0) -> 62.18 | ... T6: =IFERROR(INDEX('Data Sheet'!$B$57:$O$72, MATCH($C6, 'Data Sheet'!$A$57:$A$72, 0), MATCH(T$2, 'Data Sheet'!$B$56:$O$56, 0)), 0) -> 0
C7: Borrowings | D7: =IFERROR(INDEX('Data Sheet'!$B$57:$O$72, MATCH($C7, 'Data Sheet'!$A$57:$A$72, 0), MATCH(D$2, 'Data Sheet'!$B$56:$O$56, 0)), 0) -> 0 | E7: =IFERROR(INDEX('Data Sheet'!$B$57:$O$72, MATCH($C7, 'Data Sheet'!$A$57:$A$72, 0), MATCH(E$2, 'Data Sheet'!$B$56:$O$56, 0)), 0) -> 0 | F7: =IFERROR(INDEX('Data Sheet'!$B$57:$O$72, MATCH($C7, 'Data Sheet'!$A$57:$A$72, 0), MATCH(F$2, 'Data Sheet'!$B$56:$O$56, 0)), 0) -> 9.47 | G7: =IFERROR(INDEX('Data Sheet'!$B$57:$O$72, MATCH($C7, 'Data Sheet'!$A$57:$A$72, 0), MATCH(G$2, 'Data Sheet'!$B$56:$O$56, 0)), 0) -> 10.44 | H7: =IFERROR(INDEX('Data Sheet'!$B$57:$O$72, MATCH($C7, 'Data Sheet'!$A$57:$A$72, 0), MATCH(H$2, 'Data Sheet'!$B$56:$O$56, 0)), 0) -> 0 | I7: =IFERROR(INDEX('Data Sheet'!$B$57:$O$72, MATCH($C7, 'Data Sheet'!$A$57:$A$72, 0), MATCH(I$2, 'Data Sheet'!$B$56:$O$56, 0)), 0) -> 0 | J7: =IFERROR(INDEX('Data Sheet'!$B$57:$O$72, MATCH($C7, 'Data Sheet'!$A$57:$A$72, 0), MATCH(J$2, 'Data Sheet'!$B$56:$O$56, 0)), 0) -> 0 | K7: =IFERROR(INDEX('Data Sheet'!$B$57:$O$72, MATCH($C7, 'Data Sheet'!$A$57:$A$72, 0), MATCH(K$2, 'Data Sheet'!$B$56:$O$56, 0)), 0) -> 3.06 | ... T7: =IFERROR(INDEX('Data Sheet'!$B$57:$O$72, MATCH($C7, 'Data Sheet'!$A$57:$A$72, 0), MATCH(T$2, 'Data Sheet'!$B$56:$O$56, 0)), 0) -> 0
C8: Other Liabilities | D8: =IFERROR(INDEX('Data Sheet'!$B$57:$O$72, MATCH($C8, 'Data Sheet'!$A$57:$A$72, 0), MATCH(D$2, 'Data Sheet'!$B$56:$O$56, 0)), 0) -> 0 | E8: =IFERROR(INDEX('Data Sheet'!$B$57:$O$72, MATCH($C8, 'Data Sheet'!$A$57:$A$72, 0), MATCH(E$2, 'Data Sheet'!$B$56:$O$56, 0)), 0) -> 0 | F8: =IFERROR(INDEX('Data Sheet'!$B$57:$O$72, MATCH($C8, 'Data Sheet'!$A$57:$A$72, 0), MATCH(F$2, 'Data Sheet'!$B$56:$O$56, 0)), 0) -> 3.08 | G8: =IFERROR(INDEX('Data Sheet'!$B$57:$O$72, MATCH($C8, 'Data Sheet'!$A$57:$A$72, 0), MATCH(G$2, 'Data Sheet'!$B$56:$O$56, 0)), 0) -> 2.78 | H8: =IFERROR(INDEX('Data Sheet'!$B$57:$O$72, MATCH($C8, 'Data Sheet'!$A$57:$A$72, 0), MATCH(H$2, 'Data Sheet'!$B$56:$O$56, 0)), 0) -> 6.08 | I8: =IFERROR(INDEX('Data Sheet'!$B$57:$O$72, MATCH($C8, 'Data Sheet'!$A$57:$A$72, 0), MATCH(I$2, 'Data Sheet'!$B$56:$O$56, 0)), 0) -> 4.23 | J8: =IFERROR(INDEX('Data Sheet'!$B$57:$O$72, MATCH($C8, 'Data Sheet'!$A$57:$A$72, 0), MATCH(J$2, 'Data Sheet'!$B$56:$O$56, 0)), 0) -> 15.2 | K8: =IFERROR(INDEX('Data Sheet'!$B$57:$O$72, MATCH($C8, 'Data Sheet'!$A$57:$A$72, 0), MATCH(K$2, 'Data Sheet'!$B$56:$O$56, 0)), 0) -> 17.46 | ... T8: =IFERROR(INDEX('Data Sheet'!$B$57:$O$72, MATCH($C8, 'Data Sheet'!$A$57:$A$72, 0), MATCH(T$2, 'Data Sheet'!$B$56:$O$56, 0)), 0) -> 0
C10: Total | D10: =SUBTOTAL(9,D5:D8) -> 0 | E10: =SUBTOTAL(9,E5:E8) -> 0 | F10: =SUBTOTAL(9,F5:F8) -> 32.3 | G10: =SUBTOTAL(9,G5:G8) -> 33.85 | H10: =SUBTOTAL(9,H5:H8) -> 43.04 | I10: =SUBTOTAL(9,I5:I8) -> 47.28 | J10: =SUBTOTAL(9,J5:J8) -> 66.88 | K10: =SUBTOTAL(9,K5:K8) -> 86.76 | ... T10: =SUBTOTAL(9,T5:T8) -> 0
B12: B | C12: Application of Funds
C14: Net Block | D14: =IFERROR(INDEX('Data Sheet'!$B$57:$O$72, MATCH($C14, 'Data Sheet'!$A$57:$A$72, 0), MATCH(D$2, 'Data Sheet'!$B$56:$O$56, 0)), 0) -> 0 | E14: =IFERROR(INDEX('Data Sheet'!$B$57:$O$72, MATCH($C14, 'Data Sheet'!$A$57:$A$72, 0), MATCH(E$2, 'Data Sheet'!$B$56:$O$56, 0)), 0) -> 0 | F14: =IFERROR(INDEX('Data Sheet'!$B$57:$O$72, MATCH($C14, 'Data Sheet'!$A$57:$A$72, 0), MATCH(F$2, 'Data Sheet'!$B$56:$O$56, 0)), 0) -> 13.39 | G14: =IFERROR(INDEX('Data Sheet'!$B$57:$O$72, MATCH($C14, 'Data Sheet'!$A$57:$A$72, 0), MATCH(G$2, 'Data Sheet'!$B$56:$O$56, 0)), 0) -> 13.3 | H14: =IFERROR(INDEX('Data Sheet'!$B$57:$O$72, MATCH($C14, 'Data Sheet'!$A$57:$A$72, 0), MATCH(H$2, 'Data Sheet'!$B$56:$O$56, 0)), 0) -> 12.1 | I14: =IFERROR(INDEX('Data Sheet'!$B$57:$O$72, MATCH($C14, 'Data Sheet'!$A$57:$A$72, 0), MATCH(I$2, 'Data Sheet'!$B$56:$O$56, 0)), 0) -> 11.66 | J14: =IFERROR(INDEX('Data Sheet'!$B$57:$O$72, MATCH($C14, 'Data Sheet'!$A$57:$A$72, 0), MATCH(J$2, 'Data Sheet'!$B$56:$O$56, 0)), 0) -> 14.22 | K14: =IFERROR(INDEX('Data Sheet'!$B$57:$O$72, MATCH($C14, 'Data Sheet'!$A$57:$A$72, 0), MATCH(K$2, 'Data Sheet'!$B$56:$O$56, 0)), 0) -> 16.03 | ... T14: =IFERROR(INDEX('Data Sheet'!$B$57:$O$72, MATCH($C14, 'Data Sheet'!$A$57:$A$72, 0), MATCH(T$2, 'Data Sheet'!$B$56:$O$56, 0)), 0) -> 0
C15: Capital Work in Progress | D15: =IFERROR(INDEX('Data Sheet'!$B$57:$O$72, MATCH($C15, 'Data Sheet'!$A$57:$A$72, 0), MATCH(D$2, 'Data Sheet'!$B$56:$O$56, 0)), 0) -> 0 | E15: =IFERROR(INDEX('Data Sheet'!$B$57:$O$72, MATCH($C15, 'Data Sheet'!$A$57:$A$72, 0), MATCH(E$2, 'Data Sheet'!$B$56:$O$56, 0)), 0) -> 0 | F15: =IFERROR(INDEX('Data Sheet'!$B$57:$O$72, MATCH($C15, 'Data Sheet'!$A$57:$A$72, 0), MATCH(F$2, 'Data Sheet'!$B$56:$O$56, 0)), 0) -> 0 | G15: =IFERROR(INDEX('Data Sheet'!$B$57:$O$72, MATCH($C15, 'Data Sheet'!$A$57:$A$72, 0), MATCH(G$2, 'Data Sheet'!$B$56:$O$56, 0)), 0) -> 0 | H15: =IFERROR(INDEX('Data Sheet'!$B$57:$O$72, MATCH($C15, 'Data Sheet'!$A$57:$A$72, 0), MATCH(H$2, 'Data Sheet'!$B$56:$O$56, 0)), 0) -> 0 | I15: =IFERROR(INDEX('Data Sheet'!$B$57:$O$72, MATCH($C15, 'Data Sheet'!$A$57:$A$72, 0), MATCH(I$2, 'Data Sheet'!$B$56:$O$56, 0)), 0) -> 0.08 | J15: =IFERROR(INDEX('Data Sheet'!$B$57:$O$72, MATCH($C15, 'Data Sheet'!$A$57:$A$72, 0), MATCH(J$2, 'Data Sheet'!$B$56:$O$56, 0)), 0) -> 0 | K15: =IFERROR(INDEX('Data Sheet'!$B$57:$O$72, MATCH($C15, 'Data Sheet'!$A$57:$A$72, 0), MATCH(K$2, 'Data Sheet'!$B$56:$O$56, 0)), 0) -> 0.74 | ... T15: =IFERROR(INDEX('Data Sheet'!$B$57:$O$72, MATCH($C15, 'Data Sheet'!$A$57:$A$72, 0), MATCH(T$2, 'Data Sheet'!$B$56:$O$56, 0)), 0) -> 0
C16: Investments | D16: =IFERROR(INDEX('Data Sheet'!$B$57:$O$72, MATCH($C16, 'Data Sheet'!$A$57:$A$72, 0), MATCH(D$2, 'Data Sheet'!$B$56:$O$56, 0)), 0) -> 0 | E16: =IFERROR(INDEX('Data Sheet'!$B$57:$O$72, MATCH($C16, 'Data Sheet'!$A$57:$A$72, 0), MATCH(E$2, 'Data Sheet'!$B$56:$O$56, 0)), 0) -> 0 | F16: =IFERROR(INDEX('Data Sheet'!$B$57:$O$72, MATCH($C16, 'Data Sheet'!$A$57:$A$72, 0), MATCH(F$2, 'Data Sheet'!$B$56:$O$56, 0)), 0) -> 0 | G16: =IFERROR(INDEX('Data Sheet'!$B$57:$O$72, MATCH($C16, 'Data Sheet'!$A$57:$A$72, 0), MATCH(G$2, 'Data Sheet'!$B$56:$O$56, 0)), 0) -> 0 | H16: =IFERROR(INDEX('Data Sheet'!$B$57:$O$72, MATCH($C16, 'Data Sheet'!$A$57:$A$72, 0), MATCH(H$2, 'Data Sheet'!$B$56:$O$56, 0)), 0) -> 0 | I16: =IFERROR(INDEX('Data Sheet'!$B$57:$O$72, MATCH($C16, 'Data Sheet'!$A$57:$A$72, 0), MATCH(I$2, 'Data Sheet'!$B$56:$O$56, 0)), 0) -> 0 | J16: =IFERROR(INDEX('Data Sheet'!$B$57:$O$72, MATCH($C16, 'Data Sheet'!$A$57:$A$72, 0), MATCH(J$2, 'Data Sheet'!$B$56:$O$56, 0)), 0) -> 0 | K16: =IFERROR(INDEX('Data Sheet'!$B$57:$O$72, MATCH($C16, 'Data Sheet'!$A$57:$A$72, 0), MATCH(K$2, 'Data Sheet'!$B$56:$O$56, 0)), 0) -> 0 | ... T16: =IFERROR(INDEX('Data Sheet'!$B$57:$O$72, MATCH($C16, 'Data Sheet'!$A$57:$A$72, 0), MATCH(T$2, 'Data Sheet'!$B$56:$O$56, 0)), 0) -> 0
C17: Receivables | D17: =IFERROR(INDEX('Data Sheet'!$B$57:$O$72, MATCH($C17, 'Data Sheet'!$A$57:$A$72, 0), MATCH(D$2, 'Data Sheet'!$B$56:$O$56, 0)), 0) -> 0 | E17: =IFERROR(INDEX('Data Sheet'!$B$57:$O$72, MATCH($C17, 'Data Sheet'!$A$57:$A$72, 0), MATCH(E$2, 'Data Sheet'!$B$56:$O$56, 0)), 0) -> 0 | F17: =IFERROR(INDEX('Data Sheet'!$B$57:$O$72, MATCH($C17, 'Data Sheet'!$A$57:$A$72, 0), MATCH(F$2, 'Data Sheet'!$B$56:$O$56, 0)), 0) -> 4.09 | G17: =IFERROR(INDEX('Data Sheet'!$B$57:$O$72, MATCH($C17, 'Data Sheet'!$A$57:$A$72, 0), MATCH(G$2, 'Data Sheet'!$B$56:$O$56, 0)), 0) -> 9.62 | H17: =IFERROR(INDEX('Data Sheet'!$B$57:$O$72, MATCH($C17, 'Data Sheet'!$A$57:$A$72, 0), MATCH(H$2, 'Data Sheet'!$B$56:$O$56, 0)), 0) -> 8.92 | I17: =IFERROR(INDEX('Data Sheet'!$B$57:$O$72, MATCH($C17, 'Data Sheet'!$A$57:$A$72, 0), MATCH(I$2, 'Data Sheet'!$B$56:$O$56, 0)), 0) -> 19.26 | J17: =IFERROR(INDEX('Data Sheet'!$B$57:$O$72, MATCH($C17, 'Data Sheet'!$A$57:$A$72, 0), MATCH(J$2, 'Data Sheet'!$B$56:$O$56, 0)), 0) -> 29.65 | K17: =IFERROR(INDEX('Data Sheet'!$B$57:$O$72, MATCH($C17, 'Data Sheet'!$A$57:$A$72, 0), MATCH(K$2, 'Data Sheet'!$B$56:$O$56, 0)), 0) -> 13.13 | ... T17: =IFERROR(INDEX('Data Sheet'!$B$57:$O$72, MATCH($C17, 'Data Sheet'!$A$57:$A$72, 0), MATCH(T$2, 'Data Sheet'!$B$56:$O$56, 0)), 0) -> 0
C18: Inventory | D18: =IFERROR(INDEX('Data Sheet'!$B$57:$O$72, MATCH($C18, 'Data Sheet'!$A$57:$A$72, 0), MATCH(D$2, 'Data Sheet'!$B$56:$O$56, 0)), 0) -> 0 | E18: =IFERROR(INDEX('Data Sheet'!$B$57:$O$72, MATCH($C18, 'Data Sheet'!$A$57:$A$72, 0), MATCH(E$2, 'Data Sheet'!$B$56:$O$56, 0)), 0) -> 0 | F18: =IFERROR(INDEX('Data Sheet'!$B$57:$O$72, MATCH($C18, 'Data Sheet'!$A$57:$A$72, 0), MATCH(F$2, 'Data Sheet'!$B$56:$O$56, 0)), 0) -> 12.44 | G18: =IFERROR(INDEX('Data Sheet'!$B$57:$O$72, MATCH($C18, 'Data Sheet'!$A$57:$A$72, 0), MATCH(G$2, 'Data Sheet'!$B$56:$O$56, 0)), 0) -> 7.7 | H18: =IFERROR(INDEX('Data Sheet'!$B$57:$O$72, MATCH($C18, 'Data Sheet'!$A$57:$A$72, 0), MATCH(H$2, 'Data Sheet'!$B$56:$O$56, 0)), 0) -> 6.67 | I18: =IFERROR(INDEX('Data Sheet'!$B$57:$O$72, MATCH($C18, 'Data Sheet'!$A$57:$A$72, 0), MATCH(I$2, 'Data Sheet'!$B$56:$O$56, 0)), 0) -> 2.44 | J18: =IFERROR(INDEX('Data Sheet'!$B$57:$O$72, MATCH($C18, 'Data Sheet'!$A$57:$A$72, 0), MATCH(J$2, 'Data Sheet'!$B$56:$O$56, 0)), 0) -> 5.09 | K18: =IFERROR(INDEX('Data Sheet'!$B$57:$O$72, MATCH($C18, 'Data Sheet'!$A$57:$A$72, 0), MATCH(K$2, 'Data Sheet'!$B$56:$O$56, 0)), 0) -> 2.51 | ... T18: =IFERROR(INDEX('Data Sheet'!$B$57:$O$72, MATCH($C18, 'Data Sheet'!$A$57:$A$72, 0), MATCH(T$2, 'Data Sheet'!$B$56:$O$56, 0)), 0) -> 0
C19: Cash & Bank | D19: =IFERROR(INDEX('Data Sheet'!$B$57:$O$72, MATCH($C19, 'Data Sheet'!$A$57:$A$72, 0), MATCH(D$2, 'Data Sheet'!$B$56:$O$56, 0)), 0) -> 0 | E19: =IFERROR(INDEX('Data Sheet'!$B$57:$O$72, MATCH($C19, 'Data Sheet'!$A$57:$A$72, 0), MATCH(E$2, 'Data Sheet'!$B$56:$O$56, 0)), 0) -> 0 | F19: =IFERROR(INDEX('Data Sheet'!$B$57:$O$72, MATCH($C19, 'Data Sheet'!$A$57:$A$72, 0), MATCH(F$2, 'Data Sheet'!$B$56:$O$56, 0)), 0) -> 0.45 | G19: =IFERROR(INDEX('Data Sheet'!$B$57:$O$72, MATCH($C19, 'Data Sheet'!$A$57:$A$72, 0), MATCH(G$2, 'Data Sheet'!$B$56:$O$56, 0)), 0) -> 0.32 | H19: =IFERROR(INDEX('Data Sheet'!$B$57:$O$72, MATCH($C19, 'Data Sheet'!$A$57:$A$72, 0), MATCH(H$2, 'Data Sheet'!$B$56:$O$56, 0)), 0) -> 10.96 | I19: =IFERROR(INDEX('Data Sheet'!$B$57:$O$72, MATCH($C19, 'Data Sheet'!$A$57:$A$72, 0), MATCH(I$2, 'Data Sheet'!$B$56:$O$56, 0)), 0) -> 10.1 | J19: =IFERROR(INDEX('Data Sheet'!$B$57:$O$72, MATCH($C19, 'Data Sheet'!$A$57:$A$72, 0), MATCH(J$2, 'Data Sheet'!$B$56:$O$56, 0)), 0) -> 7.92 | K19: =IFERROR(INDEX('Data Sheet'!$B$57:$O$72, MATCH($C19, 'Data Sheet'!$A$57:$A$72, 0), MATCH(K$2, 'Data Sheet'!$B$56:$O$56, 0)), 0) -> 42.97 | ... T19: =IFERROR(INDEX('Data Sheet'!$B$57:$O$72, MATCH($C19, 'Data Sheet'!$A$57:$A$72, 0), MATCH(T$2, 'Data Sheet'!$B$56:$O$56, 0)), 0) -> 0
C20: Other Assets | D20: =IFERROR(INDEX('Data Sheet'!$B$57:$O$72, MATCH($C20, 'Data Sheet'!$A$57:$A$72, 0), MATCH(D$2, 'Data Sheet'!$B$56:$O$56, 0)), 0)-D17-D18-D19 -> 0 | E20: =IFERROR(INDEX('Data Sheet'!$B$57:$O$72, MATCH($C20, 'Data Sheet'!$A$57:$A$72, 0), MATCH(E$2, 'Data Sheet'!$B$56:$O$56, 0)), 0)-E17-E18-E19 -> 0 | F20: =IFERROR(INDEX('Data Sheet'!$B$57:$O$72, MATCH($C20, 'Data Sheet'!$A$57:$A$72, 0), MATCH(F$2, 'Data Sheet'!$B$56:$O$56, 0)), 0)-F17-F18-F19 -> 1.93 | G20: =IFERROR(INDEX('Data Sheet'!$B$57:$O$72, MATCH($C20, 'Data Sheet'!$A$57:$A$72, 0), MATCH(G$2, 'Data Sheet'!$B$56:$O$56, 0)), 0)-G17-G18-G19 -> 2.91 | H20: =IFERROR(INDEX('Data Sheet'!$B$57:$O$72, MATCH($C20, 'Data Sheet'!$A$57:$A$72, 0), MATCH(H$2, 'Data Sheet'!$B$56:$O$56, 0)), 0)-H17-H18-H19 -> 4.39 | I20: =IFERROR(INDEX('Data Sheet'!$B$57:$O$72, MATCH($C20, 'Data Sheet'!$A$57:$A$72, 0), MATCH(I$2, 'Data Sheet'!$B$56:$O$56, 0)), 0)-I17-I18-I19 -> 3.74 | J20: =IFERROR(INDEX('Data Sheet'!$B$57:$O$72, MATCH($C20, 'Data Sheet'!$A$57:$A$72, 0), MATCH(J$2, 'Data Sheet'!$B$56:$O$56, 0)), 0)-J17-J18-J19 -> 10 | K20: =IFERROR(INDEX('Data Sheet'!$B$57:$O$72, MATCH($C20, 'Data Sheet'!$A$57:$A$72, 0), MATCH(K$2, 'Data Sheet'!$B$56:$O$56, 0)), 0)-K17-K18-K19 -> 11.38 | ... T20: =IFERROR(INDEX('Data Sheet'!$B$57:$O$72, MATCH($C20, 'Data Sheet'!$A$57:$A$72, 0), MATCH(T$2, 'Data Sheet'!$B$56:$O$56, 0)), 0)-T17-T18-T19 -> 0
C22: Total | D22: =SUBTOTAL(9,D14:D20) -> 0 | E22: =SUBTOTAL(9,E14:E20) -> 0 | F22: =SUBTOTAL(9,F14:F20) -> 32.3 | G22: =SUBTOTAL(9,G14:G20) -> 33.85 | H22: =SUBTOTAL(9,H14:H20) -> 43.04 | I22: =SUBTOTAL(9,I14:I20) -> 47.28 | J22: =SUBTOTAL(9,J14:J20) -> 66.88 | K22: =SUBTOTAL(9,K14:K20) -> 86.76 | ... T22: =SUBTOTAL(9,T14:T20) -> 0
C24: Balance sheet Check | D24: =D10=D22 -> TRUE | E24: =E10=E22 -> TRUE | F24: =F10=F22 -> TRUE | G24: =G10=G22 -> TRUE | H24: =H10=H22 -> TRUE | I24: =I10=I22 -> TRUE | J24: =J10=J22 -> TRUE | K24: =K10=K22 -> TRUE | ... T24: =T10=T22 -> TRUE
B25: C. | C25: Analysis
B27: a. | C27: Net Worth | D27: =D5+D6 -> 0 | E27: =E5+E6 -> 0 | F27: =F5+F6 -> 19.75 | G27: =G5+G6 -> 20.63 | H27: =H5+H6 -> 36.96 | I27: =I5+I6 -> 43.05 | J27: =J5+J6 -> 51.68 | K27: =K5+K6 -> 66.24 | ... T27: =T5+T6 -> 0
C28: Net Worth % of Total BS | D28: =IFERROR(D$27/D$10,0) -> 0 | E28: =IFERROR(E$27/E$10,0) -> 0 | F28: =IFERROR(F$27/F$10,0) -> 0.61145511 | G28: =IFERROR(G$27/G$10,0) -> 0.60945347 | H28: =IFERROR(H$27/H$10,0) -> 0.85873606 | I28: =IFERROR(I$27/I$10,0) -> 0.91053299 | J28: =IFERROR(J$27/J$10,0) -> 0.77272727 | K28: =IFERROR(K$27/K$10,0) -> 0.76348548 | ... T28: =IFERROR(T$27/T$10,0) -> 0
B30: b. | C30: Increase in Fixed Assets | E30: =(E14+E15)-(D15+D14) -> 0 | F30: 0 | G30: =(G14+G15)-(F15+F14) -> -0.09 | H30: =(H14+H15)-(G15+G14) -> -1.2 | I30: =(I14+I15)-(H15+H14) -> -0.36 | J30: =(J14+J15)-(I15+I14) -> 2.48 | K30: =(K14+K15)-(J15+J14) -> 2.55 | L30: =(L14+L15)-(K15+K14) -> 14.94 | M30: =(M14+M15)-(L15+L14) -> 2.49 | N30: =(N14+N15)-(M15+M14) -> 25.89 | O30: =(O14+O15)-(N15+N14) -> 39.44 | P30: 0 | Q30: =(Q14+Q15)-(P15+P14) -> 0 | R30: =(R14+R15)-(Q15+Q14) -> 0 | S30: =(S14+S15)-(R15+R14) -> 0 | T30: =(T14+T15)-(S15+S14) -> 0
B32: c. | C32: Common Size Statement
C34: Equity Share Capital | D34: =IFERROR(D$5/D$10,0) -> 0 | E34: =IFERROR(E$5/E$10,0) -> 0 | F34: =IFERROR(F$5/F$10,0) -> 0.12569659 | G34: =IFERROR(G$5/G$10,0) -> 0.11994092 | H34: =IFERROR(H$5/H$10,0) -> 0.094330855 | I34: =IFERROR(I$5/I$10,0) -> 0.085871404 | J34: =IFERROR(J$5/J$10,0) -> 0.060705742 | K34: =IFERROR(K$5/K$10,0) -> 0.046795758 | ... T34: =IFERROR(T$5/T$10,0) -> 0
C35: Reserves | D35: =IFERROR(D$6/D$22,0) -> 0 | E35: =IFERROR(E$6/E$22,0) -> 0 | F35: =IFERROR(F$6/F$22,0) -> 0.48575851 | G35: =IFERROR(G$6/G$22,0) -> 0.48951256 | H35: =IFERROR(H$6/H$22,0) -> 0.7644052 | I35: =IFERROR(I$6/I$22,0) -> 0.82466159 | J35: =IFERROR(J$6/J$22,0) -> 0.71202153 | K35: =IFERROR(K$6/K$22,0) -> 0.71668972 | ... T35: =IFERROR(T$6/T$22,0) -> 0
C36: Borrowings | D36: =IFERROR(D$7/D$10,0) -> 0 | E36: =IFERROR(E$7/E$10,0) -> 0 | F36: =IFERROR(F$7/F$10,0) -> 0.29318885 | G36: =IFERROR(G$7/G$10,0) -> 0.3084195 | H36: =IFERROR(H$7/H$10,0) -> 0 | I36: =IFERROR(I$7/I$10,0) -> 0 | J36: =IFERROR(J$7/J$10,0) -> 0 | K36: =IFERROR(K$7/K$10,0) -> 0.03526971 | ... T36: =IFERROR(T$7/T$10,0) -> 0
C37: Other Liabilities | D37: =IFERROR(D$8/D$10,0) -> 0 | E37: =IFERROR(E$8/E$10,0) -> 0 | F37: =IFERROR(F$8/F$10,0) -> 0.095356037 | G37: =IFERROR(G$8/G$10,0) -> 0.082127031 | H37: =IFERROR(H$8/H$10,0) -> 0.14126394 | I37: =IFERROR(I$8/I$10,0) -> 0.089467005 | J37: =IFERROR(J$8/J$10,0) -> 0.22727273 | K37: =IFERROR(K$8/K$10,0) -> 0.20124481 | ... T37: =IFERROR(T$8/T$10,0) -> 0
C40: Net Fixed Asset | D40: =IFERROR(D$14/D$22,0) -> 0 | E40: =IFERROR(E$14/E$22,0) -> 0 | F40: =IFERROR(F$14/F$22,0) -> 0.41455108 | G40: =IFERROR(G$14/G$22,0) -> 0.3929099 | H40: =IFERROR(H$14/H$22,0) -> 0.28113383 | I40: =IFERROR(I$14/I$22,0) -> 0.24661591 | J40: =IFERROR(J$14/J$22,0) -> 0.21261962 | K40: =IFERROR(K$14/K$22,0) -> 0.18476256 | ... T40: =IFERROR(T$14/T$22,0) -> 0
C41: WIP | D41: =IFERROR(D$15/D$22,0) -> 0 | E41: =IFERROR(E$15/E$22,0) -> 0 | F41: =IFERROR(F$15/F$22,0) -> 0 | G41: =IFERROR(G$15/G$22,0) -> 0 | H41: =IFERROR(H$15/H$22,0) -> 0 | I41: =IFERROR(I$15/I$22,0) -> 0.0016920474 | J41: =IFERROR(J$15/J$22,0) -> 0 | K41: =IFERROR(K$15/K$22,0) -> 0.0085292762 | ... T41: =IFERROR(T$15/T$22,0) -> 0
C42: Receivables | D42: =IFERROR(D$17/D$22,0) -> 0 | E42: =IFERROR(E$17/E$22,0) -> 0 | F42: =IFERROR(F$17/F$22,0) -> 0.12662539 | G42: =IFERROR(G$17/G$22,0) -> 0.28419498 | H42: =IFERROR(H$17/H$22,0) -> 0.20724907 | I42: =IFERROR(I$17/I$22,0) -> 0.40736041 | J42: =IFERROR(J$17/J$22,0) -> 0.44333134 | K42: =IFERROR(K$17/K$22,0) -> 0.15133702 | ... T42: =IFERROR(T$17/T$22,0) -> 0
C43: Inventory | D43: =IFERROR(D$18/D$22,0) -> 0 | E43: =IFERROR(E$18/E$22,0) -> 0 | F43: =IFERROR(F$18/F$22,0) -> 0.38513932 | G43: =IFERROR(G$18/G$22,0) -> 0.22747415 | H43: =IFERROR(H$18/H$22,0) -> 0.15497212 | I43: =IFERROR(I$18/I$22,0) -> 0.051607445 | J43: =IFERROR(J$18/J$22,0) -> 0.076106459 | K43: =IFERROR(K$18/K$22,0) -> 0.028930383 | ... T43: =IFERROR(T$18/T$22,0) -> 0
C44: Cash & Bank | D44: =IFERROR(D$19/D$22,0) -> 0 | E44: =IFERROR(E$19/E$22,0) -> 0 | F44: =IFERROR(F$19/F$22,0) -> 0.013931889 | G44: =IFERROR(G$19/G$22,0) -> 0.0094534712 | H44: =IFERROR(H$19/H$22,0) -> 0.25464684 | I44: =IFERROR(I$19/I$22,0) -> 0.21362098 | J44: =IFERROR(J$19/J$22,0) -> 0.11842105 | K44: =IFERROR(K$19/K$22,0) -> 0.49527432 | ... T44: =IFERROR(T$19/T$22,0) -> 0
C45: Other Assets | D45: =IFERROR(D$20/D$22,0) -> 0 | E45: =IFERROR(E$20/E$22,0) -> 0 | F45: =IFERROR(F$20/F$22,0) -> 0.059752322 | G45: =IFERROR(G$20/G$22,0) -> 0.085967504 | H45: =IFERROR(H$20/H$22,0) -> 0.10199814 | I45: =IFERROR(I$20/I$22,0) -> 0.079103215 | J45: =IFERROR(J$20/J$22,0) -> 0.14952153 | K45: =IFERROR(K$20/K$22,0) -> 0.13116644 | ... T45: =IFERROR(T$20/T$22,0) -> 0
C46: Investments | D46: =IFERROR(D$16/D$22,0) -> 0 | E46: =IFERROR(E$16/E$22,0) -> 0 | F46: =IFERROR(F$16/F$22,0) -> 0 | G46: =IFERROR(G$16/G$22,0) -> 0 | H46: =IFERROR(H$16/H$22,0) -> 0 | I46: =IFERROR(I$16/I$22,0) -> 0 | J46: =IFERROR(J$16/J$22,0) -> 0 | K46: =IFERROR(K$16/K$22,0) -> 0 | ... T46: =IFERROR(T$16/T$22,0) -> 0

Sheet Sensitivity Analysis
C1: Min | D1: Max | E1: Revenue_Sensitivity
A2: Base_Revenue_Growth | B2: 10 | C2: 0 | D2: 20 | E2: 0
A3: Base_EBITDA_Margin | B3: 15 | C3: 10 | D3: 25 | E3: 0
A4: Base_Tax_Rate | B4: 25
A5: Base_WACC | B5: 12
A6: Terminal_Growth_Rate | B6: 3
A7: Working_Capital_Change | B7: 2

Sheet Working Capital
C2: Working Capital as % of Sales
C3: Inventories
C4: Receivables
C5: Loans & Advances
C6: Other Current Assets
C7: Current Tax Asset
C12: Receivables days (Low is better)
C13: Inventory Turnover (High is better)
C14: Months of RM held as Inv. (Low is better)
C15: Working capital cycle days (Rec + Inv Days)

Sheet Industry Analysis
B2: 2014 | C2: 2015 | D2: 2016 | E2: 2017 | F2: 2018 | G2: 2019 | H2: 2020 | I2: 2021 | J2: 2022 | K2: 2023 | L2: 2024 | M2: 2025 | N2: 2026 | O2: 2027 | P2: 2028 | Q2: 2029 | R2: 20230
A3: Asset Turnover ratio | B3: =IFERROR('P&L Analysis'!D$6/(BS!D$14+BS!D$15),0) -> 0 | C3: =IFERROR('P&L Analysis'!E$6/(BS!E$14+BS!E$15),0) -> 0 | D3: =IFERROR('P&L Analysis'!F$6/(BS!F$14+BS!F$15),0) -> 1.8394324 | E3: =IFERROR('P&L Analysis'!G$6/(BS!G$14+BS!G$15),0) -> 2.524812 | F3: =IFERROR('P&L Analysis'!H$6/(BS!H$14+BS!H$15),0) -> 4.2727273 | G3: =IFERROR('P&L Analysis'!I$6/(BS!I$14+BS!I$15),0) -> 4.302385 | H3: =IFERROR('P&L Analysis'!J$6/(BS!J$14+BS!J$15),0) -> 3.6511955 | I3: =IFERROR('P&L Analysis'!K$6/(BS!K$14+BS!K$15),0) -> 4.6326774 | ... R3: =IFERROR('P&L Analysis'!T$6/(BS!T$14+BS!T$15),0) -> 0
A4: How much of new asset addition can lead to increase in sales
A5: How Profits would be impacted
A6: ROE
A7: ROCE
A8: PB
A9: PE
A10: EV/EBTDA
A11: Receivables days (Low is better)
A12: Inventory Turnover (High is better)
A13: Months of RM held as Inv. (Low is better)
A14: Working capital cycle days (Rec + Inv Days)
A16: Dividend Growth
A17: Debt % of Net worth

Sheet Sheet2
B3: Net Cash generated | C3: Free cash flow | D3: CFO-Inc capex
C4: Add Change in debt
C5: Other Income
B7: Less | C7: Int Paid
C8: Dividend paid

Sheet Data Sheet
A1: COMPANY NAME | B1: AVANTEL LTD | E1: =IF(B2<>B3, "A NEW VERSION OF THE WORKSHEET IS AVAILABLE", "")
A2: LATEST VERSION | B2: 2.1 | E2: PLEASE DO NOT MAKE ANY CHANGES TO THIS SHEET
A3: CURRENT VERSION | B3: 2.1
A5: META
A6: Number of shares | B6: =IF(B9>0, B9/B8, 0) -> 26.496303
A7: Face Value | B7: 2
A8: Current Price | B8: 158.25
A9: Market Capitalization | B9: 4193.04
A14: Data sheet
A15: PROFIT & LOSS
A16: Report Date | B16: 42460 | C16: 42825 | D16: 43190 | E16: 43555 | F16: 43921 | G16: 44286 | H16: 44651 | I16: 45016 | J16: 45382 | K16: 45747
A17: Sales | B17: 24.63 | C17: 33.58 | D17: 51.7 | E17: 50.51 | F17: 51.92 | G17: 77.69 | H17: 104.94 | I17: 154.26 | J17: 223.92 | K17: 248.48
A18: Raw Material Cost | B18: 9.69 | C18: 10.02 | D18: 17.5 | E18: 11.3 | F18: 13.95 | G18: 26.57 | H18: 50.69 | I18: 76.58 | J18: 77.23 | K18: 83.22
A19: Change in Inventory | B19: 1.45 | C19: -4.77 | D19: -2.42 | E19: -2.99 | F19: 0.59 | G19: -0.42 | H19: 4 | I19: 13.82 | J19: 0.78 | K19: 19.81
A20: Power and Fuel | B20: 0.32 | C20: 0.31 | D20: 0.43 | E20: 0.47 | F20: 0.43 | G20: 0.52 | H20: 0.57 | I20: 0.82 | J20: 1.5 | K20: 2.26
A21: Other Mfr. Exp | B21: 2.04 | C21: 2.06 | D21: 3.09 | E21: 4.9 | F21: 5.14 | G21: 8.88 | H21: 7.5 | I21: 12.47 | J21: 15.77 | K21: 20.52
A22: Employee Cost | B22: 4.15 | C22: 4.85 | D22: 7.83 | E22: 8.49 | F22: 10.1 | G22: 10.43 | H22: 13.15 | I22: 16.71 | J22: 34.2 | K22: 52.12
A23: Selling and admin | B23: 5.73 | C23: 7.36 | D23: 8.28 | E23: 7.95 | F23: 7.09 | G23: 8.32 | H23: 8.77 | I23: 11.06 | J23: 8.52 | K23: 11.72
A24: Other Expenses | B24: 0.22 | C24: 0.35 | D24: 0.89 | E24: 0.19 | F24: 0.43 | G24: 0.38 | H24: 0.51 | I24: 0.96 | J24: 3.08 | K24: 3.06
A25: Other Income | B25: 0.4 | C25: 0.51 | D25: 15.44 | E25: 0.91 | F25: 1.2 | G25: 0.87 | H25: 1.37 | I25: 0.47 | J25: 1.3 | K25: 1.76
A26: Depreciation | B26: 1.74 | C26: 1.79 | D26: 1.64 | E26: 2.05 | F26: 2.71 | G26: 3.03 | H26: 3.97 | I26: 5.16 | J26: 7.06 | K26: 11.39
A27: Interest | B27: 1.94 | C27: 1.52 | D27: 0.87 | E27: 0.58 | F27: 0.85 | G27: 1.51 | H27: 1.51 | I27: 4.86 | J27: 4.17 | K27: 3.04
... A31: Dividend Amount | B31: 0.41 | C31: 0.81 | D31: 1.62 | E31: 2.03 | F31: 1.62 | G31: 1.62 | H31: 1.62 | I31: 1.62 | J31: 4.86 | K31: 4.9
A40: Quarters
A41: Report Date | B41: 44926 | C41: 45016 | D41: 45107 | E41: 45199 | F41: 45291 | G41: 45382 | H41: 45473 | I41: 45565 | J41: 45657 | K41: 45747
A42: Sales | B42: 38.68 | C42: 52.38 | D42: 68.9 | E42: 54.2 | F42: 59.1 | G42: 41.71 | H42: 51.65 | I42: 77.25 | J42: 70.44 | K42: 49.14
A43: Expenses | B43: 26.78 | C43: 33.44 | D43: 54.06 | E43: 28.69 | F43: 34.07 | G43: 22.68 | H43: 36.88 | I43: 41.98 | J43: 37.65 | K43: 36.59
A44: Other Income | B44: 0.28 | C44: 0.09 | D44: 0.13 | E44: 0.37 | F44: 0.34 | G44: 0.46 | H44: 0.3 | I44: 0.49 | J44: 0.49 | K44: 0.48
A45: Depreciation | B45: 1.35 | C45: 1.36 | D45: 1.4 | E45: 1.54 | F45: 1.75 | G45: 2.37 | H45: 2.77 | I45: 2.87 | J45: 2.95 | K45: 2.8
A46: Interest | B46: 1.55 | C46: 1.51 | D46: 1.49 | E46: 1.51 | F46: 0.87 | G46: 0.3 | H46: 0.64 | I46: 0.72 | J46: 1.02 | K46: 0.66
A47: Profit before tax | B47: 9.28 | C47: 16.16 | D47: 12.08 | E47: 22.83 | F47: 22.75 | G47: 16.82 | H47: 11.66 | I47: 32.17 | J47: 29.31 | K47: 9.57
A48: Tax | B48: 1.73 | C48: 5.63 | D48: 3.39 | E48: 6.13 | F48: 5.77 | G48: 3.73 | H48: 3.58 | I48: 8.6 | J48: 8.4 | K48: 2.21
A49: Net profit | B49: 7.55 | C49: 10.54 | D49: 8.69 | E49: 16.71 | F49: 16.97 | G49: 13.08 | H49: 8.08 | I49: 23.57 | J49: 20.9 | K49: 7.36
A50: Operating Profit | B50: 11.9 | C50: 18.94 | D50: 14.84 | E50: 25.51 | F50: 25.03 | G50: 19.03 | H50: 14.77 | I50: 35.27 | J50: 32.79 | K50: 12.55
A55: BALANCE SHEET
A56: Report Date | B56: 42460 | C56: 42825 | D56: 43190 | E56: 43555 | F56: 43921 | G56: 44286 | H56: 44651 | I56: 45016 | J56: 45382 | K56: 45747
A57: Equity Share Capital | B57: 4.06 | C57: 4.06 | D57: 4.06 | E57: 4.06 | F57: 4.06 | G57: 4.06 | H57: 4.06 | I57: 16.22 | J57: 48.65 | K57: 48.95
A58: Reserves | B58: 15.69 | C58: 16.57 | D58: 32.9 | E58: 38.99 | F58: 47.62 | G58: 62.18 | H58: 79.66 | I58: 95.66 | J58: 122.76 | K58: 199.06
A59: Borrowings | B59: 9.47 | C59: 10.44 | G59: 3.06 | H59: 15.65 | I59: 30.34 | J59: 17.5 | K59: 26.33
A60: Other Liabilities | B60: 3.08 | C60: 2.78 | D60: 6.08 | E60: 4.23 | F60: 15.2 | G60: 17.46 | H60: 10.76 | I60: 11.57 | J60: 34.06 | K60: 23.42
...
